[06/10 00:13:47] 1.8.3
[06/10 00:13:47] MUSH restarted, PID 16580, at Fri Jun 10 00:13:47 2011
[06/10 00:13:47] ANALYZING: data/indb
[06/10 00:13:47] ANALYZING: data/indb (done)
[06/10 00:13:47] LOADING: data/indb
[06/10 00:13:47] Loading database saved on Fri Jun 10 04:13:28 2011 UTC
[06/10 00:13:47] READING: done
[06/10 00:13:47] LOADING: data/indb (done)
[06/10 00:13:47] LOADING: data/maildb
[06/10 00:13:47] LOADING: data/maildb (done)
[06/10 00:13:47] LOADING: data/chatdb
[06/10 00:13:47] LOADING: data/chatdb (done)
[06/10 00:13:47] Access file access.cnf not found.
[06/10 00:13:47] Reading /home/grrm/pytest/game/mush.cnf
[06/10 00:13:47] Reading alias.cnf
[06/10 00:13:47] Reading restrict.cnf
[06/10 00:13:47] CONFIG: directive 'exit_flags' missing from cnf file, using default value.
[06/10 00:13:47] PennPy: Initializing
_DB_KEY_NAME = 0
[06/10 00:13:47] Seeding OpenSSL random number pool.
[06/10 00:13:47] Seeded after 1 cycle.
Unable to load server certificate - only anonymous ciphers supported.
16580:error:02001002:system library:fopen:No such file or directory:bss_file.c:356:fopen('server-key.crt','r')
16580:error:20074002:BIO routines:FILE_CTRL:system lib:bss_file.c:358:
16580:error:140DC002:SSL routines:SSL_CTX_use_certificate_chain_file:system lib:ssl_rsa.c:722:
Unable to load private key - only anonymous ciphers supported.
16580:error:02001002:system library:fopen:No such file or directory:bss_file.c:356:fopen('server-key.crt','r')
16580:error:20074002:BIO routines:FILE_CTRL:system lib:bss_file.c:358:
16580:error:140B0002:SSL routines:SSL_CTX_use_PrivateKey_file:system lib:ssl_rsa.c:648:
Unable to load CA certificates
16580:error:02001002:system library:fopen:No such file or directory:bss_file.c:126:fopen('/usr/share/ssl/certs/ca-bundle.crt','r')
16580:error:2006D080:BIO routines:BIO_new_file:no such file:bss_file.c:129:
16580:error:0B084002:x509 certificate routines:X509_load_cert_crl_file:system lib:by_file.c:274:
[06/10 00:13:47] Spawning info slave, communicating using socketpair, pid 16581
[06/10 00:13:47] Unable to open reboot.db in mode 'r': No such file or directory
Listening on port 8888 using IPv4.
[06/10 00:13:47] 4090 file descriptors available.
[06/10 00:13:47] RESTART FINISHED.
info_slave: trying poll event loop... ok. Using poll.
periodic() says: The current time is Fri Jun 10 00:13:48 2011
[06/10 00:13:48] PennPy: Timer hook threw exception
Traceback (most recent call last):
  File "python/main.py", line 57, in periodic
    raise AssertionError("I've been bad")
AssertionError: I've been bad
[06/10 00:14:00] PennPy: Python exception:
Traceback (most recent call last):
  File "python/main.py", line 94, in honor_pts
    return honor.pts(victim)
  File "python/honor.py", line 14, in pts
    conn = db.get_conn()
  File "python/db.py", line 7, in get_conn
    return MySQLdb.connect(host='localhost', user='e_mush', passwd='Wn5qnHyUhXmMTXbA', db='e_mush')
  File "/usr/lib/pymodules/python2.7/MySQLdb/__init__.py", line 81, in Connect
    return Connection(*args, **kwargs)
  File "/usr/lib/pymodules/python2.7/MySQLdb/connections.py", line 170, in __init__
    super(Connection, self).__init__(*args, **kwargs2)
_mysql_exceptions.OperationalError: (2002, "Can't connect to local MySQL server through socket '/var/run/mysqld/mysqld.sock' (2)")
periodic() says: The current time is Fri Jun 10 00:15:39 2011
[06/10 00:15:38] PennPy: Python exception:
Traceback (most recent call last):
  File "python/main.py", line 57, in periodic
    raise AssertionError("I've been bad")
AssertionError: I've been bad
[06/10 00:15:47] PennPy: Python exception:
TypeError: test_notify() takes exactly 2 arguments (0 given)
[06/10 00:15:54] PennPy: Python exception:
Traceback (most recent call last):
  File "python/main.py", line 39, in test_notify
    int_list = [int(pennmush.dbref(dbref)) for dbref in target.split()]
  File "python/pennmush.py", line 14, in __new__
    raise ValueError('Not a dbref string')
ValueError: Not a dbref string
