[06/19 11:11:08] 1.8.3
[06/19 11:11:08] MUSH restarted, PID 16264, at Fri Jun 19 11:11:08 2009
[06/19 11:11:08] ANALYZING: data/indb
[06/19 11:11:08] ANALYZING: data/indb (done)
[06/19 11:11:08] LOADING: data/indb
[06/19 11:11:08] Loading database saved on Thu Jun 18 19:44:25 2009 UTC
[06/19 11:11:08] READING: done
[06/19 11:11:08] LOADING: data/indb (done)
[06/19 11:11:08] LOADING: data/maildb
[06/19 11:11:08] LOADING: data/maildb (done)
[06/19 11:11:08] LOADING: data/chatdb
[06/19 11:11:08] LOADING: data/chatdb (done)
[06/19 11:11:08] Access file access.cnf not found.
[06/19 11:11:08] Reading /home/e/kilrathi/game/mush.cnf
[06/19 11:11:08] Reading alias.cnf
[06/19 11:11:08] Reading restrict.cnf
[06/19 11:11:08] CONFIG: directive 'exit_flags' missing from cnf file, using default value.
[06/19 11:11:09] PennPy: Initializing
_DB_KEY_NAME = 0
[06/19 11:11:09] Seeding OpenSSL random number pool.
[06/19 11:11:09] Seeded after 1 cycle.
Unable to load server certificate - only anonymous ciphers supported.
16264:error:02001002:system library:fopen:No such file or directory:bss_file.c:352:fopen('server-key.crt','r')
16264:error:20074002:BIO routines:FILE_CTRL:system lib:bss_file.c:354:
16264:error:140DC002:SSL routines:SSL_CTX_use_certificate_chain_file:system lib:ssl_rsa.c:720:
Unable to load private key - only anonymous ciphers supported.
16264:error:02001002:system library:fopen:No such file or directory:bss_file.c:352:fopen('server-key.crt','r')
16264:error:20074002:BIO routines:FILE_CTRL:system lib:bss_file.c:354:
16264:error:140B0002:SSL routines:SSL_CTX_use_PrivateKey_file:system lib:ssl_rsa.c:648:
Unable to load CA certificates
16264:error:02001002:system library:fopen:No such file or directory:bss_file.c:122:fopen('/usr/share/ssl/certs/ca-bundle.crt','r')
16264:error:2006D080:BIO routines:BIO_new_file:no such file:bss_file.c:125:
16264:error:0B084002:x509 certificate routines:X509_load_cert_crl_file:system lib:by_file.c:274:
[06/19 11:11:09] Spawning info slave, communicating using socketpair, pid 16265
[06/19 11:11:09] Unable to open reboot.db in mode 'r': No such file or directory
Listening on port 8888 using IPv4.
[06/19 11:11:09] 1018 file descriptors available.
[06/19 11:11:09] RESTART FINISHED.
info_slave: trying poll event loop... ok. Using poll.
periodic() says: The current time is Fri Jun 19 11:11:10 2009
[06/19 11:11:10] PennPy: Timer hook threw exception
Traceback (most recent call last):
  File "python/main.py", line 57, in periodic
    raise AssertionError("I've been bad")
AssertionError: I've been bad
